2018-10-23 18:34:54,570 ERROR: Exception on /reset_password_request [POST] [in c:\users\gusta\appdata\local\programs\python\python37-32\lib\site-packages\flask\app.py:1761]
Traceback (most recent call last):
  File "c:\users\gusta\appdata\local\programs\python\python37-32\lib\site-packages\flask\app.py", line 2292, in wsgi_app
    response = self.full_dispatch_request()
  File "c:\users\gusta\appdata\local\programs\python\python37-32\lib\site-packages\flask\app.py", line 1815, in full_dispatch_request
    rv = self.handle_user_exception(e)
  File "c:\users\gusta\appdata\local\programs\python\python37-32\lib\site-packages\flask\app.py", line 1718, in handle_user_exception
    reraise(exc_type, exc_value, tb)
  File "c:\users\gusta\appdata\local\programs\python\python37-32\lib\site-packages\flask\_compat.py", line 35, in reraise
    raise value
  File "c:\users\gusta\appdata\local\programs\python\python37-32\lib\site-packages\flask\app.py", line 1813, in full_dispatch_request
    rv = self.dispatch_request()
  File "c:\users\gusta\appdata\local\programs\python\python37-32\lib\site-packages\flask\app.py", line 1799, in dispatch_request
    return self.view_functions[rule.endpoint](**req.view_args)
  File "C:\Users\gusta\OneDrive\Documentos\GitHub\pjApagao\app\routes.py", line 128, in reset_password_request
    send_password_reset_email(user)
  File "C:\Users\gusta\OneDrive\Documentos\GitHub\pjApagao\app\email.py", line 28, in send_password_reset_email
    user=user, token=token))
  File "c:\users\gusta\appdata\local\programs\python\python37-32\lib\site-packages\flask\templating.py", line 135, in render_template
    context, ctx.app)
  File "c:\users\gusta\appdata\local\programs\python\python37-32\lib\site-packages\flask\templating.py", line 117, in _render
    rv = template.render(context)
  File "c:\users\gusta\appdata\local\programs\python\python37-32\lib\site-packages\jinja2\asyncsupport.py", line 76, in render
    return original_render(self, *args, **kwargs)
  File "c:\users\gusta\appdata\local\programs\python\python37-32\lib\site-packages\jinja2\environment.py", line 1008, in render
    return self.environment.handle_exception(exc_info, True)
  File "c:\users\gusta\appdata\local\programs\python\python37-32\lib\site-packages\jinja2\environment.py", line 780, in handle_exception
    reraise(exc_type, exc_value, tb)
  File "c:\users\gusta\appdata\local\programs\python\python37-32\lib\site-packages\jinja2\_compat.py", line 37, in reraise
    raise value.with_traceback(tb)
  File "C:\Users\gusta\OneDrive\Documentos\GitHub\pjApagao\app\templates\reset_password.html", line 1, in top-level template code
    {% extends "base.html" %}
  File "C:\Users\gusta\OneDrive\Documentos\GitHub\pjApagao\app\templates\base.html", line 33, in top-level template code
    {% block content %}{% endblock %}
  File "C:\Users\gusta\OneDrive\Documentos\GitHub\pjApagao\app\templates\reset_password.html", line 6, in block "content"
    {{ form.hidden_tag() }}
  File "c:\users\gusta\appdata\local\programs\python\python37-32\lib\site-packages\jinja2\environment.py", line 430, in getattr
    return getattr(obj, attribute)
jinja2.exceptions.UndefinedError: 'form' is undefined
2018-10-23 19:09:06,509 INFO: Pjapagao startup [in C:\Users\gusta\OneDrive\Documentos\GitHub\pjApagao\app\__init__.py:48]
2018-10-23 19:09:40,502 ERROR: Exception on /register [POST] [in c:\users\gusta\appdata\local\programs\python\python37-32\lib\site-packages\flask\app.py:1761]
Traceback (most recent call last):
  File "c:\users\gusta\appdata\local\programs\python\python37-32\lib\site-packages\flask\app.py", line 2292, in wsgi_app
    response = self.full_dispatch_request()
  File "c:\users\gusta\appdata\local\programs\python\python37-32\lib\site-packages\flask\app.py", line 1815, in full_dispatch_request
    rv = self.handle_user_exception(e)
  File "c:\users\gusta\appdata\local\programs\python\python37-32\lib\site-packages\flask\app.py", line 1718, in handle_user_exception
    reraise(exc_type, exc_value, tb)
  File "c:\users\gusta\appdata\local\programs\python\python37-32\lib\site-packages\flask\_compat.py", line 35, in reraise
    raise value
  File "c:\users\gusta\appdata\local\programs\python\python37-32\lib\site-packages\flask\app.py", line 1813, in full_dispatch_request
    rv = self.dispatch_request()
  File "c:\users\gusta\appdata\local\programs\python\python37-32\lib\site-packages\flask\app.py", line 1799, in dispatch_request
    return self.view_functions[rule.endpoint](**req.view_args)
  File "C:\Users\gusta\OneDrive\Documentos\GitHub\pjApagao\app\routes.py", line 67, in register
    if form.validate_on_submit():
  File "c:\users\gusta\appdata\local\programs\python\python37-32\lib\site-packages\flask_wtf\form.py", line 101, in validate_on_submit
    return self.is_submitted() and self.validate()
  File "c:\users\gusta\appdata\local\programs\python\python37-32\lib\site-packages\wtforms\form.py", line 310, in validate
    return super(Form, self).validate(extra)
  File "c:\users\gusta\appdata\local\programs\python\python37-32\lib\site-packages\wtforms\form.py", line 152, in validate
    if not field.validate(self, extra):
  File "c:\users\gusta\appdata\local\programs\python\python37-32\lib\site-packages\wtforms\fields\core.py", line 206, in validate
    stop_validation = self._run_validation_chain(form, chain)
  File "c:\users\gusta\appdata\local\programs\python\python37-32\lib\site-packages\wtforms\fields\core.py", line 226, in _run_validation_chain
    validator(form, self)
  File "C:\Users\gusta\OneDrive\Documentos\GitHub\pjApagao\app\forms.py", line 23, in validate_username
    user = User.query.filter_by(username=username.data).first()
NameError: name 'User' is not defined
2018-10-23 19:11:36,315 INFO: Pjapagao startup [in C:\Users\gusta\OneDrive\Documentos\GitHub\pjApagao\app\__init__.py:48]
2018-10-23 19:11:52,911 ERROR: Exception on /register [POST] [in c:\users\gusta\appdata\local\programs\python\python37-32\lib\site-packages\flask\app.py:1761]
Traceback (most recent call last):
  File "c:\users\gusta\appdata\local\programs\python\python37-32\lib\site-packages\flask\app.py", line 2292, in wsgi_app
    response = self.full_dispatch_request()
  File "c:\users\gusta\appdata\local\programs\python\python37-32\lib\site-packages\flask\app.py", line 1815, in full_dispatch_request
    rv = self.handle_user_exception(e)
  File "c:\users\gusta\appdata\local\programs\python\python37-32\lib\site-packages\flask\app.py", line 1718, in handle_user_exception
    reraise(exc_type, exc_value, tb)
  File "c:\users\gusta\appdata\local\programs\python\python37-32\lib\site-packages\flask\_compat.py", line 35, in reraise
    raise value
  File "c:\users\gusta\appdata\local\programs\python\python37-32\lib\site-packages\flask\app.py", line 1813, in full_dispatch_request
    rv = self.dispatch_request()
  File "c:\users\gusta\appdata\local\programs\python\python37-32\lib\site-packages\flask\app.py", line 1799, in dispatch_request
    return self.view_functions[rule.endpoint](**req.view_args)
  File "C:\Users\gusta\OneDrive\Documentos\GitHub\pjApagao\app\routes.py", line 67, in register
    if form.validate_on_submit():
  File "c:\users\gusta\appdata\local\programs\python\python37-32\lib\site-packages\flask_wtf\form.py", line 101, in validate_on_submit
    return self.is_submitted() and self.validate()
  File "c:\users\gusta\appdata\local\programs\python\python37-32\lib\site-packages\wtforms\form.py", line 310, in validate
    return super(Form, self).validate(extra)
  File "c:\users\gusta\appdata\local\programs\python\python37-32\lib\site-packages\wtforms\form.py", line 152, in validate
    if not field.validate(self, extra):
  File "c:\users\gusta\appdata\local\programs\python\python37-32\lib\site-packages\wtforms\fields\core.py", line 206, in validate
    stop_validation = self._run_validation_chain(form, chain)
  File "c:\users\gusta\appdata\local\programs\python\python37-32\lib\site-packages\wtforms\fields\core.py", line 226, in _run_validation_chain
    validator(form, self)
  File "C:\Users\gusta\OneDrive\Documentos\GitHub\pjApagao\app\forms.py", line 23, in validate_username
    user = User.query.filter_by(username=username.data).first()
NameError: name 'User' is not defined
2018-10-23 19:13:39,495 INFO: Pjapagao startup [in C:\Users\gusta\OneDrive\Documentos\GitHub\pjApagao\app\__init__.py:48]
