2018-10-24 13:27:54,574 INFO: Pjapagao startup [in /home/ggrecco/Documentos/Pj_Apagao/app/__init__.py:48]
2018-10-25 07:47:03,628 INFO: Pjapagao startup [in /home/ggrecco/Documentos/Pj_Apagao/app/__init__.py:48]
2018-10-25 07:47:07,704 INFO: Pjapagao startup [in /home/ggrecco/Documentos/Pj_Apagao/app/__init__.py:48]
2018-10-25 13:19:29,959 INFO: Pjapagao startup [in /home/ggrecco/Documentos/Pj_Apagao/app/__init__.py:48]
2018-10-25 13:33:57,835 INFO: Pjapagao startup [in /home/ggrecco/Documentos/Pj_Apagao/app/__init__.py:48]
2018-10-25 13:46:05,606 INFO: Pjapagao startup [in /home/ggrecco/Documentos/Pj_Apagao/app/__init__.py:48]
2018-10-25 14:23:18,643 INFO: Pjapagao startup [in /home/ggrecco/Documentos/Pj_Apagao/app/__init__.py:48]
2018-10-25 14:46:18,076 INFO: Pjapagao startup [in /home/ggrecco/Documentos/Pj_Apagao/app/__init__.py:48]
2018-10-25 14:46:37,999 ERROR: Exception on /tackle2 [GET] [in /root/.virtualenvs/pjApagao/lib/python3.6/site-packages/flask/app.py:1761]
Traceback (most recent call last):
  File "/root/.virtualenvs/pjApagao/lib/python3.6/site-packages/flask/app.py", line 2292, in wsgi_app
    response = self.full_dispatch_request()
  File "/root/.virtualenvs/pjApagao/lib/python3.6/site-packages/flask/app.py", line 1815, in full_dispatch_request
    rv = self.handle_user_exception(e)
  File "/root/.virtualenvs/pjApagao/lib/python3.6/site-packages/flask/app.py", line 1718, in handle_user_exception
    reraise(exc_type, exc_value, tb)
  File "/root/.virtualenvs/pjApagao/lib/python3.6/site-packages/flask/_compat.py", line 35, in reraise
    raise value
  File "/root/.virtualenvs/pjApagao/lib/python3.6/site-packages/flask/app.py", line 1813, in full_dispatch_request
    rv = self.dispatch_request()
  File "/root/.virtualenvs/pjApagao/lib/python3.6/site-packages/flask/app.py", line 1799, in dispatch_request
    return self.view_functions[rule.endpoint](**req.view_args)
  File "/home/ggrecco/Documentos/Pj_Apagao/app/routes.py", line 127, in tackle2
    arquivo = open('dados.json', 'r')
FileNotFoundError: [Errno 2] No such file or directory: 'dados.json'
2018-10-25 14:47:58,113 INFO: Pjapagao startup [in /home/ggrecco/Documentos/Pj_Apagao/app/__init__.py:48]
2018-10-25 14:48:09,733 ERROR: Exception on /tackle2 [GET] [in /root/.virtualenvs/pjApagao/lib/python3.6/site-packages/flask/app.py:1761]
Traceback (most recent call last):
  File "/root/.virtualenvs/pjApagao/lib/python3.6/site-packages/flask/app.py", line 2292, in wsgi_app
    response = self.full_dispatch_request()
  File "/root/.virtualenvs/pjApagao/lib/python3.6/site-packages/flask/app.py", line 1815, in full_dispatch_request
    rv = self.handle_user_exception(e)
  File "/root/.virtualenvs/pjApagao/lib/python3.6/site-packages/flask/app.py", line 1718, in handle_user_exception
    reraise(exc_type, exc_value, tb)
  File "/root/.virtualenvs/pjApagao/lib/python3.6/site-packages/flask/_compat.py", line 35, in reraise
    raise value
  File "/root/.virtualenvs/pjApagao/lib/python3.6/site-packages/flask/app.py", line 1813, in full_dispatch_request
    rv = self.dispatch_request()
  File "/root/.virtualenvs/pjApagao/lib/python3.6/site-packages/flask/app.py", line 1799, in dispatch_request
    return self.view_functions[rule.endpoint](**req.view_args)
  File "/home/ggrecco/Documentos/Pj_Apagao/app/routes.py", line 128, in tackle2
    dados = json.load(arquivo)
NameError: name 'json' is not defined
2018-10-25 14:48:33,327 INFO: Pjapagao startup [in /home/ggrecco/Documentos/Pj_Apagao/app/__init__.py:48]
